{
  "timestamp": "2025-08-08T19:04:29.146221",
  "total_passed": 7,
  "total_failed": 25,
  "total_time": 4.95802903175354,
  "results": [
    {
      "module": "test_cache_database_integration.py",
      "passed": 0,
      "failed": 1,
      "elapsed_time": 0.10333728790283203,
      "returncode": 1,
      "output": "",
      "error": "Traceback (most recent call last):\n  File \"/home/jclee/app/blacklist/tests/integration/test_cache_database_integration.py\", line 15, in <module>\n    from src.core.unified_service import UnifiedBlacklistService\nModuleNotFoundError: No module named 'src'\n"
    },
    {
      "module": "test_cicd_mocks.py",
      "passed": 0,
      "failed": 0,
      "elapsed_time": 0.0947575569152832,
      "returncode": 0,
      "output": "",
      "error": ""
    },
    {
      "module": "test_cicd_pipeline.py",
      "passed": 7,
      "failed": 0,
      "elapsed_time": 0.6833293437957764,
      "returncode": 0,
      "output": "============================= test session starts ==============================\nplatform linux -- Python 3.10.12, pytest-7.4.3, pluggy-1.6.0 -- /usr/bin/python3\ncachedir: .pytest_cache\nmetadata: {'Python': '3.10.12', 'Platform': 'Linux-6.8.0-1031-azure-x86_64-with-glibc2.35', 'Packages': {'pytest': '7.4.3', 'pluggy': '1.6.0'}, 'Plugins': {'metadata': '3.1.1', 'asyncio': '0.21.1', 'cov': '4.1.0', 'xdist': '3.8.0', 'timeout': '2.2.0', 'html': '4.1.1', 'anyio': '3.7.1', 'mock': '3.14.1'}}\nrootdir: /home/jclee/app/blacklist/tests\nconfigfile: pytest.ini\nplugins: metadata-3.1.1, asyncio-0.21.1, cov-4.1.0, xdist-3.8.0, timeout-2.2.0, html-4.1.1, anyio-3.7.1, mock-3.14.1\nasyncio: mode=strict\ncollecting ... collected 25 items\n\ntests/integration/test_cicd_pipeline.py::TestCICDPipelineTriggers::test_main_branch_push_triggers_full_pipeline FAILED [  4%]\ntests/integration/test_cicd_pipeline.py::TestCICDPipelineTriggers::test_develop_branch_push_triggers_appropriate_workflow FAILED [  8%]\ntests/integration/test_cicd_pipeline.py::TestCICDPipelineTriggers::test_pr_creation_triggers_quality_checks_only FAILED [ 12%]\ntests/integration/test_cicd_pipeline.py::TestCICDPipelineTriggers::test_path_ignoring_for_docs FAILED [ 16%]\ntests/integration/test_cicd_pipeline.py::TestCICDPipelineTriggers::test_concurrency_cancellation FAILED [ 20%]\ntests/integration/test_cicd_pipeline.py::TestCodeQualityStage::test_python_linting_catches_style_violations FAILED [ 24%]\ntests/integration/test_cicd_pipeline.py::TestCodeQualityStage::test_security_scanning_detects_hardcoded_secrets PASSED [ 28%]\ntests/integration/test_cicd_pipeline.py::TestCodeQualityStage::test_dependency_vulnerability_scanning PASSED [ 32%]\ntests/integration/test_cicd_pipeline.py::TestCodeQualityStage::test_code_coverage_threshold_enforcement FAILED [ 36%]\ntests/integration/test_cicd_pipeline.py::TestBuildStage::test_docker_multi_stage_build FAILED [ 40%]\ntests/integration/test_cicd_pipeline.py::TestBuildStage::test_build_cache_utilization FAILED [ 44%]\ntests/integration/test_cicd_pipeline.py::TestBuildStage::test_image_tagging_strategy FAILED [ 48%]\ntests/integration/test_cicd_pipeline.py::TestBuildStage::test_registry_authentication PASSED [ 52%]\ntests/integration/test_cicd_pipeline.py::TestDeploymentStage::test_argocd_application_sync FAILED [ 56%]\ntests/integration/test_cicd_pipeline.py::TestDeploymentStage::test_image_update_detection FAILED [ 60%]\ntests/integration/test_cicd_pipeline.py::TestDeploymentStage::test_health_check_validation FAILED [ 64%]\ntests/integration/test_cicd_pipeline.py::TestDeploymentStage::test_rollback_on_deployment_failure PASSED [ 68%]\ntests/integration/test_cicd_pipeline.py::TestDeploymentStage::test_multi_cluster_deployment FAILED [ 72%]\ntests/integration/test_cicd_pipeline.py::TestEndToEndFlow::test_full_pipeline_from_commit_to_deployment PASSED [ 76%]\ntests/integration/test_cicd_pipeline.py::TestEndToEndFlow::test_failure_recovery_at_each_stage FAILED [ 80%]\ntests/integration/test_cicd_pipeline.py::TestEndToEndFlow::test_notification_and_alerting FAILED [ 84%]\ntests/integration/test_cicd_pipeline.py::TestPipelineRefactoring::test_configuration_extraction FAILED [ 88%]\ntests/integration/test_cicd_pipeline.py::TestPipelineRefactoring::test_pipeline_hooks_availability PASSED [ 92%]\ntests/integration/test_cicd_pipeline.py::TestPipelineRefactoring::test_script_modularity FAILED [ 96%]\ntests/integration/test_cicd_pipeline.py::TestPipelineRefactoring::test_dry_run_mode_support PASSED [100%]\n\n=================================== FAILURES ===================================\n____ TestCICDPipelineTriggers.test_main_branch_push_triggers_full_pipeline _____\ntests/integration/test_cicd_pipeline.py:34: in test_main_branch_push_triggers_full_pipeline\n    assert workflow_path.exists()\nE   AssertionError: assert False\nE    +  where False = <bound method Path.exists of PosixPath('.github/workflows/complete-cicd-pipeline.yml')>()\nE    +    where <bound method Path.exists of PosixPath('.github/workflows/complete-cicd-pipeline.yml')> = PosixPath('.github/workflows/complete-cicd-pipeline.yml').exists\n_ TestCICDPipelineTriggers.test_develop_branch_push_triggers_appropriate_workflow _\ntests/integration/test_cicd_pipeline.py:54: in test_develop_branch_push_triggers_appropriate_workflow\n    with open(workflow_path) as f:\nE   FileNotFoundError: [Errno 2] No such file or directory: '.github/workflows/complete-cicd-pipeline.yml'\n____ TestCICDPipelineTriggers.test_pr_creation_triggers_quality_checks_only ____\ntests/integration/test_cicd_pipeline.py:63: in test_pr_creation_triggers_quality_checks_only\n    with open(workflow_path) as f:\nE   FileNotFoundError: [Errno 2] No such file or directory: '.github/workflows/complete-cicd-pipeline.yml'\n_____________ TestCICDPipelineTriggers.test_path_ignoring_for_docs _____________\ntests/integration/test_cicd_pipeline.py:72: in test_path_ignoring_for_docs\n    with open(workflow_path) as f:\nE   FileNotFoundError: [Errno 2] No such file or directory: '.github/workflows/complete-cicd-pipeline.yml'\n____________ TestCICDPipelineTriggers.test_concurrency_cancellation ____________\ntests/integration/test_cicd_pipeline.py:83: in test_concurrency_cancellation\n    with open(workflow_path) as f:\nE   FileNotFoundError: [Errno 2] No such file or directory: '.github/workflows/complete-cicd-pipeline.yml'\n______ TestCodeQualityStage.test_python_linting_catches_style_violations _______\ntests/integration/test_cicd_pipeline.py:115: in test_python_linting_catches_style_violations\n    result = subprocess.run(\n/usr/lib/python3.10/subprocess.py:503: in run\n    with Popen(*popenargs, **kwargs) as process:\n/usr/lib/python3.10/subprocess.py:971: in __init__\n    self._execute_child(args, executable, preexec_fn, close_fds,\n/usr/lib/python3.10/subprocess.py:1863: in _execute_child\n    raise child_exception_type(errno_num, err_msg, err_filename)\nE   FileNotFoundError: [Errno 2] No such file or directory: 'python'\n________ TestCodeQualityStage.test_code_coverage_threshold_enforcement _________\ntests/integration/test_cicd_pipeline.py:167: in test_code_coverage_threshold_enforcement\n    assert \"--cov\" in content or \"coverage\" in content.lower()\nE   assert ('--cov' in '[pytest]\\ntestpaths = tests\\npython_files = test_*.py\\npython_classes = Test*\\npython_functions = test_*\\naddopts = \\n    -v\\n    --tb=short\\n    --strict-markers\\n    --disable-warnings\\n    -p no:warnings\\n    --ignore=scripts/\\n    --ignore=archive/\\nmarkers =\\n    slow: marks tests as slow (deselect with \\'-m \"not slow\"\\')\\n    integration: marks tests as integration tests\\n    unit: marks tests as unit tests\\n    manual: marks tests that require manual intervention' or 'coverage' in '[pytest]\\ntestpaths = tests\\npython_files = test_*.py\\npython_classes = test*\\npython_functions = test_*\\naddopts = \\n    -v\\n    --tb=short\\n    --strict-markers\\n    --disable-warnings\\n    -p no:warnings\\n    --ignore=scripts/\\n    --ignore=archive/\\nmarkers =\\n    slow: marks tests as slow (deselect with \\'-m \"not slow\"\\')\\n    integration: marks tests as integration tests\\n    unit: marks tests as unit tests\\n    manual: marks tests that require manual intervention')\nE    +  where '[pytest]\\ntestpaths = tests\\npython_files = test_*.py\\npython_classes = test*\\npython_functions = test_*\\naddopts = \\n    -v\\n    --tb=short\\n    --strict-markers\\n    --disable-warnings\\n    -p no:warnings\\n    --ignore=scripts/\\n    --ignore=archive/\\nmarkers =\\n    slow: marks tests as slow (deselect with \\'-m \"not slow\"\\')\\n    integration: marks tests as integration tests\\n    unit: marks tests as unit tests\\n    manual: marks tests that require manual intervention' = <built-in method lower of str object at 0x703e6016ae30>()\nE    +    where <built-in method lower of str object at 0x703e6016ae30> = '[pytest]\\ntestpaths = tests\\npython_files = test_*.py\\npython_classes = Test*\\npython_functions = test_*\\naddopts = \\n    -v\\n    --tb=short\\n    --strict-markers\\n    --disable-warnings\\n    -p no:warnings\\n    --ignore=scripts/\\n    --ignore=archive/\\nmarkers =\\n    slow: marks tests as slow (deselect with \\'-m \"not slow\"\\')\\n    integration: marks tests as integration tests\\n    unit: marks tests as unit tests\\n    manual: marks tests that require manual intervention'.lower\n_________________ TestBuildStage.test_docker_multi_stage_build _________________\ntests/integration/test_cicd_pipeline.py:186: in test_docker_multi_stage_build\n    assert \"FROM python:3.10-slim\" in dockerfile_content\nE   assert 'FROM python:3.10-slim' in '# Multi-stage Python FastAPI Blacklist Management System\\n# Stage 1: Builder for production dependencies\\nFROM python:3.9 AS builder\\n\\n# Build arguments\\nARG BUILD_TIME\\nARG CACHE_BUST=1\\nENV BUILD_TIME=${BUILD_TIME}\\nENV CACHE_BUST=${CACHE_BUST}\\nENV TZ=Asia/Seoul\\n\\n# python:3.9 already includes gcc, g++, and other build tools\\n# No need to install them separately, saving significant build time\\n\\n# Create app user\\nRUN useradd --create-home --shell /bin/bash app\\n\\n# Set working directory\\nWORKDIR /app\\n\\n# Copy requirements first for better caching\\nCOPY requirements.txt .\\n\\n# Install Python dependencies (production only)\\nRUN pip install --no-cache-dir --upgrade pip && \\\\\\n    pip install --no-cache-dir -r requirements.txt\\n\\n# Stage 2: Production image with all dependencies\\n# Using regular python:3.9 instead of slim to have curl pre-installed\\nFROM python:3.9 AS production\\n\\n# Build arguments\\nARG BUILD_TIME=\"Unknown\"\\nENV BUILD_TIME=${BUILD_TIME}\\nENV TZ=Asia/Seoul\\nENV PYTHONPATH=/app\\n\\n# Verify curl is available (should be pre-installed in python:3.9)\\nRUN which curl && curl --version\\n\\n# Create app user\\nRUN useradd --create-home --shell /bin/bash app\\n\\n# Set working directory\\nWORKDIR /app\\n\\n# Copy Python packages from builder\\nCOPY --from=builder /usr/local/lib/python3.9/site-packages /usr/local/lib/python3.9/site-packages\\nCOPY --from=builder /usr/local/bin /usr/local/bin\\n\\n# Copy application code\\nCOPY --chown=app:app . .\\n\\n# Create necessary directories\\nRUN mkdir -p instance data logs && \\\\\\n    chown -R app:app /app\\n\\n# Switch to app user\\nUSER app\\n\\n# Create database directory  \\nRUN mkdir -p instance\\n\\n# Health check\\nHEALTHCHECK --interval=30s --timeout=10s --start-period=5s --retries=3 \\\\\\n    CMD curl -f http://localhost:${PORT:-8541}/health || exit 1\\n\\n# Expose port (configurable)\\nEXPOSE ${PORT:-8541}\\n\\n# Copy startup script\\nCOPY --chown=app:app startup.sh /app/startup.sh\\nRUN chmod +x /app/startup.sh\\n\\n# Initialize database if needed and start application\\nCMD [\"/app/startup.sh\"]'\n_________________ TestBuildStage.test_build_cache_utilization __________________\ntests/integration/test_cicd_pipeline.py:192: in test_build_cache_utilization\n    with open(workflow_path) as f:\nE   FileNotFoundError: [Errno 2] No such file or directory: '.github/workflows/complete-cicd-pipeline.yml'\n__________________ TestBuildStage.test_image_tagging_strategy __________________\ntests/integration/test_cicd_pipeline.py:200: in test_image_tagging_strategy\n    with open(workflow_path) as f:\nE   FileNotFoundError: [Errno 2] No such file or directory: '.github/workflows/complete-cicd-pipeline.yml'\n_______________ TestDeploymentStage.test_argocd_application_sync _______________\ntests/integration/test_cicd_pipeline.py:232: in test_argocd_application_sync\n    assert argocd_app_path.exists()\nE   AssertionError: assert False\nE    +  where False = <bound method Path.exists of PosixPath('k8s/argocd-app-clean.yaml')>()\nE    +    where <bound method Path.exists of PosixPath('k8s/argocd-app-clean.yaml')> = PosixPath('k8s/argocd-app-clean.yaml').exists\n_______________ TestDeploymentStage.test_image_update_detection ________________\ntests/integration/test_cicd_pipeline.py:245: in test_image_update_detection\n    with open(argocd_app_path) as f:\nE   FileNotFoundError: [Errno 2] No such file or directory: 'k8s/argocd-app-clean.yaml'\n_______________ TestDeploymentStage.test_health_check_validation _______________\ntests/integration/test_cicd_pipeline.py:259: in test_health_check_validation\n    assert deployment_path.exists()\nE   AssertionError: assert False\nE    +  where False = <bound method Path.exists of PosixPath('k8s/deployment.yaml')>()\nE    +    where <bound method Path.exists of PosixPath('k8s/deployment.yaml')> = PosixPath('k8s/deployment.yaml').exists\n______________ TestDeploymentStage.test_multi_cluster_deployment _______________\ntests/integration/test_cicd_pipeline.py:291: in test_multi_cluster_deployment\n    assert multi_deploy_script.exists()\nE   AssertionError: assert False\nE    +  where False = <bound method Path.exists of PosixPath('scripts/multi-deploy.sh')>()\nE    +    where <bound method Path.exists of PosixPath('scripts/multi-deploy.sh')> = PosixPath('scripts/multi-deploy.sh').exists\n_____________ TestEndToEndFlow.test_failure_recovery_at_each_stage _____________\ntests/integration/test_cicd_pipeline.py:369: in test_failure_recovery_at_each_stage\n    with open(workflow_path) as f:\nE   FileNotFoundError: [Errno 2] No such file or directory: '.github/workflows/complete-cicd-pipeline.yml'\n_______________ TestEndToEndFlow.test_notification_and_alerting ________________\ntests/integration/test_cicd_pipeline.py:379: in test_notification_and_alerting\n    assert issue_workflow.exists()\nE   AssertionError: assert False\nE    +  where False = <bound method Path.exists of PosixPath('.github/workflows/create-issue-on-failure.yml')>()\nE    +    where <bound method Path.exists of PosixPath('.github/workflows/create-issue-on-failure.yml')> = PosixPath('.github/workflows/create-issue-on-failure.yml').exists\n____________ TestPipelineRefactoring.test_configuration_extraction _____________\ntests/integration/test_cicd_pipeline.py:396: in test_configuration_extraction\n    with open(workflow_path) as f:\nE   FileNotFoundError: [Errno 2] No such file or directory: '.github/workflows/complete-cicd-pipeline.yml'\n________________ TestPipelineRefactoring.test_script_modularity ________________\ntests/integration/test_cicd_pipeline.py:429: in test_script_modularity\n    assert (scripts_dir / script).exists()\nE   AssertionError: assert False\nE    +  where False = <bound method Path.exists of PosixPath('scripts/deploy.sh')>()\nE    +    where <bound method Path.exists of PosixPath('scripts/deploy.sh')> = (PosixPath('scripts') / 'deploy.sh').exists\n=========================== short test summary info ============================\nFAILED tests/integration/test_cicd_pipeline.py::TestCICDPipelineTriggers::test_main_branch_push_triggers_full_pipeline\nFAILED tests/integration/test_cicd_pipeline.py::TestCICDPipelineTriggers::test_develop_branch_push_triggers_appropriate_workflow\nFAILED tests/integration/test_cicd_pipeline.py::TestCICDPipelineTriggers::test_pr_creation_triggers_quality_checks_only\nFAILED tests/integration/test_cicd_pipeline.py::TestCICDPipelineTriggers::test_path_ignoring_for_docs\nFAILED tests/integration/test_cicd_pipeline.py::TestCICDPipelineTriggers::test_concurrency_cancellation\nFAILED tests/integration/test_cicd_pipeline.py::TestCodeQualityStage::test_python_linting_catches_style_violations\nFAILED tests/integration/test_cicd_pipeline.py::TestCodeQualityStage::test_code_coverage_threshold_enforcement\nFAILED tests/integration/test_cicd_pipeline.py::TestBuildStage::test_docker_multi_stage_build\nFAILED tests/integration/test_cicd_pipeline.py::TestBuildStage::test_build_cache_utilization\nFAILED tests/integration/test_cicd_pipeline.py::TestBuildStage::test_image_tagging_strategy\nFAILED tests/integration/test_cicd_pipeline.py::TestDeploymentStage::test_argocd_application_sync\nFAILED tests/integration/test_cicd_pipeline.py::TestDeploymentStage::test_image_update_detection\nFAILED tests/integration/test_cicd_pipeline.py::TestDeploymentStage::test_health_check_validation\nFAILED tests/integration/test_cicd_pipeline.py::TestDeploymentStage::test_multi_cluster_deployment\nFAILED tests/integration/test_cicd_pipeline.py::TestEndToEndFlow::test_failure_recovery_at_each_stage\nFAILED tests/integration/test_cicd_pipeline.py::TestEndToEndFlow::test_notification_and_alerting\nFAILED tests/integration/test_cicd_pipeline.py::TestPipelineRefactoring::test_configuration_extraction\nFAILED tests/integration/test_cicd_pipeline.py::TestPipelineRefactoring::test_script_modularity\n========================= 18 failed, 7 passed in 0.40s =========================\n",
      "error": ""
    },
    {
      "module": "test_cicd_refactoring.py",
      "passed": 0,
      "failed": 1,
      "elapsed_time": 0.11502957344055176,
      "returncode": 1,
      "output": "",
      "error": "Traceback (most recent call last):\n  File \"/home/jclee/app/blacklist/tests/integration/test_cicd_refactoring.py\", line 19, in <module>\n    from scripts.lib.cicd_testability import (BuildStage, CodeQualityStage,\nModuleNotFoundError: No module named 'scripts.lib.cicd_testability'\n"
    },
    {
      "module": "test_collection_endpoints_integration.py",
      "passed": 0,
      "failed": 1,
      "elapsed_time": 0.1359255313873291,
      "returncode": 1,
      "output": "",
      "error": "Traceback (most recent call last):\n  File \"/home/jclee/app/blacklist/tests/integration/test_collection_endpoints_integration.py\", line 15, in <module>\n    from src.core.unified_routes import unified_bp\nModuleNotFoundError: No module named 'src'\n"
    },
    {
      "module": "test_collection_system_integration.py",
      "passed": 0,
      "failed": 6,
      "elapsed_time": 0.4159517288208008,
      "returncode": 1,
      "output": "\n============================================================\n\ud83d\ude80 Running Collection System Integration Tests\n============================================================\n\n\ud83e\uddea Testing CollectionManager initialization...\n\u274c CollectionManager Initialization test failed with error: 'CollectionManager' object has no attribute 'collection_enabled'\n\n\ud83e\uddea Testing collection enable/disable cycle...\n\u274c Collection Enable/Disable Cycle test failed with error: \n\n\ud83e\uddea Testing REGTECH collector integration (mocked)...\n\u274c REGTECH Collector Mock test failed with error: RegtechSimpleCollector.__init__() got an unexpected keyword argument 'username'\n\n\ud83e\uddea Testing data lifecycle integration...\n\u2705 Data insertion test passed\n\u2705 Expiration handling test passed\n\u274c Data Lifecycle test failed with error: 'CollectionManager' object has no attribute 'get_collection_status'\n\n\ud83e\uddea Testing collection error handling...\n\u274c Error Handling test failed with error: RegtechSimpleCollector.__init__() got an unexpected keyword argument 'username'\n\n\ud83e\uddea Testing UnifiedBlacklistService integration...\n\u274c UnifiedService Integration test failed with error: No module named 'src.core.blacklist_unified.statistics_service'\n\n============================================================\n\ud83d\udcca Test Results: 0 passed, 6 failed\n============================================================\n",
      "error": "Collection force disabled by environment variable\nTraceback (most recent call last):\n  File \"/home/jclee/app/blacklist/tests/integration/test_collection_system_integration.py\", line 390, in run_all_collection_integration_tests\n    if test_func():\n  File \"/home/jclee/app/blacklist/tests/integration/test_collection_system_integration.py\", line 33, in test_collection_manager_initialization\n    manager.collection_enabled == False\nAttributeError: 'CollectionManager' object has no attribute 'collection_enabled'\nCollection force disabled by environment variable\nTraceback (most recent call last):\n  File \"/home/jclee/app/blacklist/tests/integration/test_collection_system_integration.py\", line 390, in run_all_collection_integration_tests\n    if test_func():\n  File \"/home/jclee/app/blacklist/tests/integration/test_collection_system_integration.py\", line 73, in test_collection_enable_disable_cycle\n    assert result[\"success\"] == True\nAssertionError\nTraceback (most recent call last):\n  File \"/home/jclee/app/blacklist/tests/integration/test_collection_system_integration.py\", line 390, in run_all_collection_integration_tests\n    if test_func():\n  File \"/home/jclee/app/blacklist/tests/integration/test_collection_system_integration.py\", line 154, in test_regtech_collector_mock_integration\n    collector = RegtechSimpleCollector(\nTypeError: RegtechSimpleCollector.__init__() got an unexpected keyword argument 'username'\nCollection force disabled by environment variable\nTraceback (most recent call last):\n  File \"/home/jclee/app/blacklist/tests/integration/test_collection_system_integration.py\", line 390, in run_all_collection_integration_tests\n    if test_func():\n  File \"/home/jclee/app/blacklist/tests/integration/test_collection_system_integration.py\", line 254, in test_data_lifecycle_integration\n    stats = manager.get_collection_status()\nAttributeError: 'CollectionManager' object has no attribute 'get_collection_status'\nTraceback (most recent call last):\n  File \"/home/jclee/app/blacklist/tests/integration/test_collection_system_integration.py\", line 390, in run_all_collection_integration_tests\n    if test_func():\n  File \"/home/jclee/app/blacklist/tests/integration/test_collection_system_integration.py\", line 286, in test_collection_error_handling\n    collector = RegtechSimpleCollector(\nTypeError: RegtechSimpleCollector.__init__() got an unexpected keyword argument 'username'\nTraceback (most recent call last):\n  File \"/home/jclee/app/blacklist/tests/integration/test_collection_system_integration.py\", line 390, in run_all_collection_integration_tests\n    if test_func():\n  File \"/home/jclee/app/blacklist/tests/integration/test_collection_system_integration.py\", line 326, in test_unified_service_integration\n    service = UnifiedBlacklistService()\n  File \"/home/jclee/app/blacklist/tests/integration/../../src/core/services/unified_service_core.py\", line 42, in __init__\n    self.container = get_container()\n  File \"/home/jclee/app/blacklist/tests/integration/../../src/core/containers/utils.py\", line 25, in get_container\n    _container = BlacklistContainer()\n  File \"/home/jclee/app/blacklist/tests/integration/../../src/core/containers/blacklist_container.py\", line 24, in __init__\n    self._configure_core_services()\n  File \"/home/jclee/app/blacklist/tests/integration/../../src/core/containers/blacklist_container.py\", line 34, in _configure_core_services\n    from ..blacklist_unified import UnifiedBlacklistManager\n  File \"/home/jclee/app/blacklist/tests/integration/../../src/core/blacklist_unified/__init__.py\", line 3, in <module>\n    from .manager import UnifiedBlacklistManager\n  File \"/home/jclee/app/blacklist/tests/integration/../../src/core/blacklist_unified/manager.py\", line 17, in <module>\n    from .statistics_service import StatisticsService\nModuleNotFoundError: No module named 'src.core.blacklist_unified.statistics_service'\n"
    },
    {
      "module": "test_comprehensive.py",
      "passed": 0,
      "failed": 1,
      "elapsed_time": 2.105595350265503,
      "returncode": 1,
      "output": "\ud83d\ude80 \uc218\uc9d1 \uc2dc\uc2a4\ud15c \ud1b5\ud569 \ud14c\uc2a4\ud2b8 \uc2dc\uc791\n============================================================\n\u274c \uc2dc\uc2a4\ud15c \ud5ec\uc2a4\uccb4\ud06c: \uc5f0\uacb0 \uc2e4\ud328: HTTPConnectionPool(host='localhost', port=8541): Max retries exceeded with url: /health (Caused by NewConnectionError('<urllib3.connection.HTTPConnection object at 0x7c41ad888760>: Failed to establish a new connection: [Errno 111] Connection refused'))\n\u274c \uc218\uc9d1 \uc2dc\uc2a4\ud15c \ud65c\uc131\ud654: \uc624\ub958: HTTPConnectionPool(host='localhost', port=8541): Max retries exceeded with url: /api/collection/enable (Caused by NewConnectionError('<urllib3.connection.HTTPConnection object at 0x7c41ad888760>: Failed to establish a new connection: [Errno 111] Connection refused'))\n\u274c REGTECH \uc218\uc9d1: \uc624\ub958: HTTPConnectionPool(host='localhost', port=8541): Max retries exceeded with url: /api/collection/regtech/trigger (Caused by NewConnectionError('<urllib3.connection.HTTPConnection object at 0x7c41ad888c70>: Failed to establish a new connection: [Errno 111] Connection refused'))\n\u2705 SECUDIUM \uc218\uc9d1: SECUDIUM \uc218\uc9d1\uc774 \ube44\ud65c\uc131\ud654\ub418\uc5c8\uc2b5\ub2c8\ub2e4 (\uc0ac\uc6a9\uc790 \uc694\uccad)\n\u274c API \uc5d4\ub4dc\ud3ec\uc778\ud2b8: \uc2dc\uc2a4\ud15c \ud1b5\uacc4: \uc624\ub958: HTTPConnectionPool(host='localhost', port=8541): Max retries exceeded with url: /api/stats (Caused by NewConnectionError('<urllib3.connection.HTTPConnection object at 0x7c41ad889000>: Failed to establish a new connection: [Errno 111] Connection refused'))\n\u274c API \uc5d4\ub4dc\ud3ec\uc778\ud2b8: \ud65c\uc131 \ube14\ub799\ub9ac\uc2a4\ud2b8: \uc624\ub958: HTTPConnectionPool(host='localhost', port=8541): Max retries exceeded with url: /api/blacklist/active (Caused by NewConnectionError('<urllib3.connection.HTTPConnection object at 0x7c41ad889330>: Failed to establish a new connection: [Errno 111] Connection refused'))\n\u274c API \uc5d4\ub4dc\ud3ec\uc778\ud2b8: FortiGate \ud615\uc2dd: \uc624\ub958: HTTPConnectionPool(host='localhost', port=8541): Max retries exceeded with url: /api/fortigate (Caused by NewConnectionError('<urllib3.connection.HTTPConnection object at 0x7c41ad889690>: Failed to establish a new connection: [Errno 111] Connection refused'))\n\u274c API \uc5d4\ub4dc\ud3ec\uc778\ud2b8: \uc218\uc9d1 \uc0c1\ud0dc: \uc624\ub958: HTTPConnectionPool(host='localhost', port=8541): Max retries exceeded with url: /api/collection/status (Caused by NewConnectionError('<urllib3.connection.HTTPConnection object at 0x7c41ad8899f0>: Failed to establish a new connection: [Errno 111] Connection refused'))\n\u274c \uc131\ub2a5 \ud14c\uc2a4\ud2b8: \uc624\ub958: HTTPConnectionPool(host='localhost', port=8541): Max retries exceeded with url: /api/stats (Caused by NewConnectionError('<urllib3.connection.HTTPConnection object at 0x7c41ad889cc0>: Failed to establish a new connection: [Errno 111] Connection refused'))\n\n============================================================\n\ud83d\udcca \ud14c\uc2a4\ud2b8 \uacb0\uacfc \uc694\uc57d\n============================================================\n\ucd1d \ud14c\uc2a4\ud2b8: 9\n\uc131\uacf5: 1\n\uc2e4\ud328: 8\n\uc131\uacf5\ub960: 11.1%\n\uc2e4\ud589\uc2dc\uac04: 2.0\ucd08\n\n\u274c \uc2e4\ud328\ud55c \ud14c\uc2a4\ud2b8:\n  - \uc2dc\uc2a4\ud15c \ud5ec\uc2a4\uccb4\ud06c: \uc5f0\uacb0 \uc2e4\ud328: HTTPConnectionPool(host='localhost', port=8541): Max retries exceeded with url: /health (Caused by NewConnectionError('<urllib3.connection.HTTPConnection object at 0x7c41ad888760>: Failed to establish a new connection: [Errno 111] Connection refused'))\n  - \uc218\uc9d1 \uc2dc\uc2a4\ud15c \ud65c\uc131\ud654: \uc624\ub958: HTTPConnectionPool(host='localhost', port=8541): Max retries exceeded with url: /api/collection/enable (Caused by NewConnectionError('<urllib3.connection.HTTPConnection object at 0x7c41ad888760>: Failed to establish a new connection: [Errno 111] Connection refused'))\n  - REGTECH \uc218\uc9d1: \uc624\ub958: HTTPConnectionPool(host='localhost', port=8541): Max retries exceeded with url: /api/collection/regtech/trigger (Caused by NewConnectionError('<urllib3.connection.HTTPConnection object at 0x7c41ad888c70>: Failed to establish a new connection: [Errno 111] Connection refused'))\n  - API \uc5d4\ub4dc\ud3ec\uc778\ud2b8: \uc2dc\uc2a4\ud15c \ud1b5\uacc4: \uc624\ub958: HTTPConnectionPool(host='localhost', port=8541): Max retries exceeded with url: /api/stats (Caused by NewConnectionError('<urllib3.connection.HTTPConnection object at 0x7c41ad889000>: Failed to establish a new connection: [Errno 111] Connection refused'))\n  - API \uc5d4\ub4dc\ud3ec\uc778\ud2b8: \ud65c\uc131 \ube14\ub799\ub9ac\uc2a4\ud2b8: \uc624\ub958: HTTPConnectionPool(host='localhost', port=8541): Max retries exceeded with url: /api/blacklist/active (Caused by NewConnectionError('<urllib3.connection.HTTPConnection object at 0x7c41ad889330>: Failed to establish a new connection: [Errno 111] Connection refused'))\n  - API \uc5d4\ub4dc\ud3ec\uc778\ud2b8: FortiGate \ud615\uc2dd: \uc624\ub958: HTTPConnectionPool(host='localhost', port=8541): Max retries exceeded with url: /api/fortigate (Caused by NewConnectionError('<urllib3.connection.HTTPConnection object at 0x7c41ad889690>: Failed to establish a new connection: [Errno 111] Connection refused'))\n  - API \uc5d4\ub4dc\ud3ec\uc778\ud2b8: \uc218\uc9d1 \uc0c1\ud0dc: \uc624\ub958: HTTPConnectionPool(host='localhost', port=8541): Max retries exceeded with url: /api/collection/status (Caused by NewConnectionError('<urllib3.connection.HTTPConnection object at 0x7c41ad8899f0>: Failed to establish a new connection: [Errno 111] Connection refused'))\n  - \uc131\ub2a5 \ud14c\uc2a4\ud2b8: \uc624\ub958: HTTPConnectionPool(host='localhost', port=8541): Max retries exceeded with url: /api/stats (Caused by NewConnectionError('<urllib3.connection.HTTPConnection object at 0x7c41ad889cc0>: Failed to establish a new connection: [Errno 111] Connection refused'))\n\n\ud83c\udfaf \uad8c\uc7a5\uc0ac\ud56d:\n  \ud83d\udd27 \uc2e4\ud328\ud55c \ud14c\uc2a4\ud2b8\ub97c \ud655\uc778\ud558\uace0 \ubb38\uc81c\ub97c \ud574\uacb0\ud558\uc138\uc694.\n  \ud83d\udccb REGTECH/SECUDIUM \uc790\uaca9\uc99d\uba85\uc774 \uc5c6\ub294 \uacbd\uc6b0 \ub85c\uadf8\uc778 \uc2e4\ud328\ub294 \uc815\uc0c1\uc785\ub2c8\ub2e4.\n",
      "error": ""
    },
    {
      "module": "test_deployment_integration.py",
      "passed": 0,
      "failed": 5,
      "elapsed_time": 0.05530977249145508,
      "returncode": 1,
      "output": "\n============================================================\n\ud83d\ude80 Running Deployment Integration Tests\n============================================================\n\n\ud83e\uddea Testing Dockerfile build validation...\n\u2705 Dockerfile exists\n\u2705 Dockerfile syntax validation passed\n\u2705 Multi-stage build detected\n\u2705 Non-root user configured\n\n\ud83e\uddea Testing Kubernetes manifests...\n\u274c Kubernetes Manifests test failed with error: Missing deployment.yaml\n\n\ud83e\uddea Testing ArgoCD application configuration...\n\u274c ArgoCD Application test failed with error: No ArgoCD application files found\n\n\ud83e\uddea Testing Docker Compose configuration...\n\u2705 Volumes configured\n\u2705 Docker Compose validation passed\n\n\ud83e\uddea Testing deployment scripts...\n\u2705 k8s-management.sh validation passed\n\n\ud83e\uddea Testing registry configuration...\n\u274c Registry Configuration test failed with error: No registry configuration found\n\n\ud83e\uddea Testing health probe configuration...\n\u274c Health Probes test failed with error: [Errno 2] No such file or directory: 'k8s-gitops/base/deployment.yaml'\n\n\ud83e\uddea Testing resource limits configuration...\n\u274c Resource Limits test failed with error: [Errno 2] No such file or directory: 'k8s-gitops/base/deployment.yaml'\n\n\ud83e\uddea Testing HPA configuration...\n\u26a0\ufe0f HPA not configured (optional)\n\n============================================================\n\ud83d\udcca Test Results: 4 passed, 5 failed\n============================================================\n",
      "error": "Traceback (most recent call last):\n  File \"/home/jclee/app/blacklist/tests/integration/test_deployment_integration.py\", line 395, in run_all_deployment_integration_tests\n    if test_func():\n  File \"/home/jclee/app/blacklist/tests/integration/test_deployment_integration.py\", line 66, in test_kubernetes_manifests\n    assert file_path.exists(), f\"Missing {file_name}\"\nAssertionError: Missing deployment.yaml\nTraceback (most recent call last):\n  File \"/home/jclee/app/blacklist/tests/integration/test_deployment_integration.py\", line 395, in run_all_deployment_integration_tests\n    if test_func():\n  File \"/home/jclee/app/blacklist/tests/integration/test_deployment_integration.py\", line 140, in test_argocd_application\n    assert len(app_files) > 0, \"No ArgoCD application files found\"\nAssertionError: No ArgoCD application files found\nTraceback (most recent call last):\n  File \"/home/jclee/app/blacklist/tests/integration/test_deployment_integration.py\", line 395, in run_all_deployment_integration_tests\n    if test_func():\n  File \"/home/jclee/app/blacklist/tests/integration/test_deployment_integration.py\", line 258, in test_registry_configuration\n    assert len(registry_configs) > 0, \"No registry configuration found\"\nAssertionError: No registry configuration found\nTraceback (most recent call last):\n  File \"/home/jclee/app/blacklist/tests/integration/test_deployment_integration.py\", line 395, in run_all_deployment_integration_tests\n    if test_func():\n  File \"/home/jclee/app/blacklist/tests/integration/test_deployment_integration.py\", line 276, in test_health_probes\n    with open(deployment_path, \"r\") as f:\nFileNotFoundError: [Errno 2] No such file or directory: 'k8s-gitops/base/deployment.yaml'\nTraceback (most recent call last):\n  File \"/home/jclee/app/blacklist/tests/integration/test_deployment_integration.py\", line 395, in run_all_deployment_integration_tests\n    if test_func():\n  File \"/home/jclee/app/blacklist/tests/integration/test_deployment_integration.py\", line 313, in test_resource_limits\n    with open(deployment_path, \"r\") as f:\nFileNotFoundError: [Errno 2] No such file or directory: 'k8s-gitops/base/deployment.yaml'\n"
    },
    {
      "module": "test_e2e_integration.py",
      "passed": 0,
      "failed": 5,
      "elapsed_time": 0.3903200626373291,
      "returncode": 1,
      "output": "{\"timestamp\": \"2025-08-08T10:04:28.171994+00:00\", \"level\": null, \"name\": \"src.core.app_compact\", \"message\": \"Failed to create application\", \"exc_info\": \"Traceback (most recent call last):\\n  File \\\"/home/jclee/app/blacklist/tests/integration/../../src/core/app_compact.py\\\", line 74, in create_app\\n    container = get_container()\\n  File \\\"/home/jclee/app/blacklist/tests/integration/../../src/core/containers/utils.py\\\", line 25, in get_container\\n    _container = BlacklistContainer()\\n  File \\\"/home/jclee/app/blacklist/tests/integration/../../src/core/containers/blacklist_container.py\\\", line 24, in __init__\\n    self._configure_core_services()\\n  File \\\"/home/jclee/app/blacklist/tests/integration/../../src/core/containers/blacklist_container.py\\\", line 34, in _configure_core_services\\n    from ..blacklist_unified import UnifiedBlacklistManager\\n  File \\\"/home/jclee/app/blacklist/tests/integration/../../src/core/blacklist_unified/__init__.py\\\", line 3, in <module>\\n    from .manager import UnifiedBlacklistManager\\n  File \\\"/home/jclee/app/blacklist/tests/integration/../../src/core/blacklist_unified/manager.py\\\", line 17, in <module>\\n    from .statistics_service import StatisticsService\\nModuleNotFoundError: No module named 'src.core.blacklist_unified.statistics_service'\", \"context\": {\"critical\": true}}\n\n============================================================\n\ud83d\ude80 Running End-to-End Integration Tests\n============================================================\n\n\ud83e\uddea Testing complete data flow (E2E)...\n\n1\ufe0f\u20e3 Initializing application...\n{\"timestamp\": \"2025-08-08T10:04:28.215787+00:00\", \"level\": null, \"name\": \"src.core.app_compact\", \"message\": \"Failed to create application\", \"exc_info\": \"Traceback (most recent call last):\\n  File \\\"/home/jclee/app/blacklist/tests/integration/../../src/core/app_compact.py\\\", line 74, in create_app\\n    container = get_container()\\n  File \\\"/home/jclee/app/blacklist/tests/integration/../../src/core/containers/utils.py\\\", line 25, in get_container\\n    _container = BlacklistContainer()\\n  File \\\"/home/jclee/app/blacklist/tests/integration/../../src/core/containers/blacklist_container.py\\\", line 24, in __init__\\n    self._configure_core_services()\\n  File \\\"/home/jclee/app/blacklist/tests/integration/../../src/core/containers/blacklist_container.py\\\", line 34, in _configure_core_services\\n    from ..blacklist_unified import UnifiedBlacklistManager\\n  File \\\"/home/jclee/app/blacklist/tests/integration/../../src/core/blacklist_unified/__init__.py\\\", line 3, in <module>\\n    from .manager import UnifiedBlacklistManager\\n  File \\\"/home/jclee/app/blacklist/tests/integration/../../src/core/blacklist_unified/manager.py\\\", line 17, in <module>\\n    from .statistics_service import StatisticsService\\nModuleNotFoundError: No module named 'src.core.blacklist_unified.statistics_service'\", \"context\": {\"critical\": true}}\n2\ufe0f\u20e3 Health check...\n\u274c Complete Data Flow test failed with error: \n\n\ud83e\uddea Testing deployment pipeline simulation (E2E)...\n\n1\ufe0f\u20e3 Simulating code change...\n\u2705 Version file found\n\n2\ufe0f\u20e3 Validating CI/CD workflow...\n\u274c Deployment Pipeline Simulation test failed with error: CI/CD workflow not found\n\n\ud83e\uddea Testing error recovery flow (E2E)...\n{\"timestamp\": \"2025-08-08T10:04:28.222913+00:00\", \"level\": null, \"name\": \"src.core.app_compact\", \"message\": \"Failed to create application\", \"exc_info\": \"Traceback (most recent call last):\\n  File \\\"/home/jclee/app/blacklist/tests/integration/../../src/core/app_compact.py\\\", line 74, in create_app\\n    container = get_container()\\n  File \\\"/home/jclee/app/blacklist/tests/integration/../../src/core/containers/utils.py\\\", line 25, in get_container\\n    _container = BlacklistContainer()\\n  File \\\"/home/jclee/app/blacklist/tests/integration/../../src/core/containers/blacklist_container.py\\\", line 24, in __init__\\n    self._configure_core_services()\\n  File \\\"/home/jclee/app/blacklist/tests/integration/../../src/core/containers/blacklist_container.py\\\", line 34, in _configure_core_services\\n    from ..blacklist_unified import UnifiedBlacklistManager\\n  File \\\"/home/jclee/app/blacklist/tests/integration/../../src/core/blacklist_unified/__init__.py\\\", line 3, in <module>\\n    from .manager import UnifiedBlacklistManager\\n  File \\\"/home/jclee/app/blacklist/tests/integration/../../src/core/blacklist_unified/manager.py\\\", line 17, in <module>\\n    from .statistics_service import StatisticsService\\nModuleNotFoundError: No module named 'src.core.blacklist_unified.statistics_service'\", \"context\": {\"critical\": true}}\n\n1\ufe0f\u20e3 Testing invalid request handling...\n\u274c Error Recovery Flow test failed with error: \n\n\ud83e\uddea Testing performance under load (E2E)...\n{\"timestamp\": \"2025-08-08T10:04:28.228585+00:00\", \"level\": null, \"name\": \"src.core.app_compact\", \"message\": \"Failed to create application\", \"exc_info\": \"Traceback (most recent call last):\\n  File \\\"/home/jclee/app/blacklist/tests/integration/../../src/core/app_compact.py\\\", line 74, in create_app\\n    container = get_container()\\n  File \\\"/home/jclee/app/blacklist/tests/integration/../../src/core/containers/utils.py\\\", line 25, in get_container\\n    _container = BlacklistContainer()\\n  File \\\"/home/jclee/app/blacklist/tests/integration/../../src/core/containers/blacklist_container.py\\\", line 24, in __init__\\n    self._configure_core_services()\\n  File \\\"/home/jclee/app/blacklist/tests/integration/../../src/core/containers/blacklist_container.py\\\", line 34, in _configure_core_services\\n    from ..blacklist_unified import UnifiedBlacklistManager\\n  File \\\"/home/jclee/app/blacklist/tests/integration/../../src/core/blacklist_unified/__init__.py\\\", line 3, in <module>\\n    from .manager import UnifiedBlacklistManager\\n  File \\\"/home/jclee/app/blacklist/tests/integration/../../src/core/blacklist_unified/manager.py\\\", line 17, in <module>\\n    from .statistics_service import StatisticsService\\nModuleNotFoundError: No module named 'src.core.blacklist_unified.statistics_service'\", \"context\": {\"critical\": true}}\n\n1\ufe0f\u20e3 Testing single request performance...\n\u274c Performance Under Load test failed with error: \n\n\ud83e\uddea Testing multi-source integration (E2E)...\n{\"timestamp\": \"2025-08-08T10:04:28.234950+00:00\", \"level\": null, \"name\": \"src.core.app_compact\", \"message\": \"Failed to create application\", \"exc_info\": \"Traceback (most recent call last):\\n  File \\\"/home/jclee/app/blacklist/tests/integration/../../src/core/app_compact.py\\\", line 74, in create_app\\n    container = get_container()\\n  File \\\"/home/jclee/app/blacklist/tests/integration/../../src/core/containers/utils.py\\\", line 25, in get_container\\n    _container = BlacklistContainer()\\n  File \\\"/home/jclee/app/blacklist/tests/integration/../../src/core/containers/blacklist_container.py\\\", line 24, in __init__\\n    self._configure_core_services()\\n  File \\\"/home/jclee/app/blacklist/tests/integration/../../src/core/containers/blacklist_container.py\\\", line 34, in _configure_core_services\\n    from ..blacklist_unified import UnifiedBlacklistManager\\n  File \\\"/home/jclee/app/blacklist/tests/integration/../../src/core/blacklist_unified/__init__.py\\\", line 3, in <module>\\n    from .manager import UnifiedBlacklistManager\\n  File \\\"/home/jclee/app/blacklist/tests/integration/../../src/core/blacklist_unified/manager.py\\\", line 17, in <module>\\n    from .statistics_service import StatisticsService\\nModuleNotFoundError: No module named 'src.core.blacklist_unified.statistics_service'\", \"context\": {\"critical\": true}}\n\n1\ufe0f\u20e3 Checking collection status...\n\u274c Multi-Source Integration test failed with error: \n\n============================================================\n\ud83d\udcca Test Results: 0 passed, 5 failed\n============================================================\n",
      "error": "Traceback (most recent call last):\n  File \"/home/jclee/app/blacklist/tests/integration/test_e2e_integration.py\", line 444, in run_all_e2e_integration_tests\n    if test_func():\n  File \"/home/jclee/app/blacklist/tests/integration/test_e2e_integration.py\", line 44, in test_complete_data_flow\n    assert response.status_code == 200\nAssertionError\nTraceback (most recent call last):\n  File \"/home/jclee/app/blacklist/tests/integration/test_e2e_integration.py\", line 444, in run_all_e2e_integration_tests\n    if test_func():\n  File \"/home/jclee/app/blacklist/tests/integration/test_e2e_integration.py\", line 171, in test_deployment_pipeline_simulation\n    assert workflow_file.exists(), \"CI/CD workflow not found\"\nAssertionError: CI/CD workflow not found\nTraceback (most recent call last):\n  File \"/home/jclee/app/blacklist/tests/integration/test_e2e_integration.py\", line 444, in run_all_e2e_integration_tests\n    if test_func():\n  File \"/home/jclee/app/blacklist/tests/integration/test_e2e_integration.py\", line 230, in test_error_recovery_flow\n    assert response.status_code == 400\nAssertionError\nTraceback (most recent call last):\n  File \"/home/jclee/app/blacklist/tests/integration/test_e2e_integration.py\", line 444, in run_all_e2e_integration_tests\n    if test_func():\n  File \"/home/jclee/app/blacklist/tests/integration/test_e2e_integration.py\", line 294, in test_performance_under_load\n    assert response.status_code == 200\nAssertionError\nTraceback (most recent call last):\n  File \"/home/jclee/app/blacklist/tests/integration/test_e2e_integration.py\", line 444, in run_all_e2e_integration_tests\n    if test_func():\n  File \"/home/jclee/app/blacklist/tests/integration/test_e2e_integration.py\", line 391, in test_multi_source_integration\n    assert response.status_code == 200\nAssertionError\n"
    },
    {
      "module": "test_error_handling_edge_cases.py",
      "passed": 0,
      "failed": 1,
      "elapsed_time": 0.09472274780273438,
      "returncode": 1,
      "output": "",
      "error": "Traceback (most recent call last):\n  File \"/home/jclee/app/blacklist/tests/integration/test_error_handling_edge_cases.py\", line 13, in <module>\n    from .edge_case_tests import (TestDataEdgeCases, TestDateEdgeCases,\nImportError: attempted relative import with no known parent package\n"
    },
    {
      "module": "test_error_recovery.py",
      "passed": 0,
      "failed": 1,
      "elapsed_time": 0.10547852516174316,
      "returncode": 1,
      "output": "",
      "error": "Traceback (most recent call last):\n  File \"/home/jclee/app/blacklist/tests/integration/test_error_recovery.py\", line 10, in <module>\n    from src.core.unified_service import UnifiedBlacklistService\nModuleNotFoundError: No module named 'src'\n"
    },
    {
      "module": "test_helpers.py",
      "passed": 0,
      "failed": 0,
      "elapsed_time": 0.15252971649169922,
      "returncode": 0,
      "output": "",
      "error": ""
    },
    {
      "module": "test_service_core.py",
      "passed": 0,
      "failed": 1,
      "elapsed_time": 0.10426759719848633,
      "returncode": 1,
      "output": "",
      "error": "Traceback (most recent call last):\n  File \"/home/jclee/app/blacklist/tests/integration/test_service_core.py\", line 10, in <module>\n    from src.core.unified_service import UnifiedBlacklistService\nModuleNotFoundError: No module named 'src'\n"
    },
    {
      "module": "test_service_integration.py",
      "passed": 0,
      "failed": 1,
      "elapsed_time": 0.051493167877197266,
      "returncode": 1,
      "output": "",
      "error": "Traceback (most recent call last):\n  File \"/home/jclee/app/blacklist/tests/integration/test_service_integration.py\", line 7, in <module>\n    from .test_cache_database_integration import TestCacheDatabaseIntegration\nImportError: attempted relative import with no known parent package\n"
    },
    {
      "module": "test_unified_routes_integration.py",
      "passed": 0,
      "failed": 1,
      "elapsed_time": 0.34998106956481934,
      "returncode": 1,
      "output": "",
      "error": "Traceback (most recent call last):\n  File \"/home/jclee/app/blacklist/tests/integration/test_unified_routes_integration.py\", line 17, in <module>\n    from src.core.unified_routes import unified_bp\n  File \"/home/jclee/app/blacklist/tests/integration/../../src/core/unified_routes.py\", line 11, in <module>\n    from .routes.admin_routes import admin_routes_bp\n  File \"/home/jclee/app/blacklist/tests/integration/../../src/core/routes/__init__.py\", line 3, in <module>\n    from .admin_routes import admin_routes_bp\n  File \"/home/jclee/app/blacklist/tests/integration/../../src/core/routes/admin_routes.py\", line 23, in <module>\n    service = get_unified_service()\n  File \"/home/jclee/app/blacklist/tests/integration/../../src/core/services/unified_service_factory.py\", line 27, in get_unified_service\n    _unified_service_instance = UnifiedBlacklistService()\n  File \"/home/jclee/app/blacklist/tests/integration/../../src/core/services/unified_service_core.py\", line 42, in __init__\n    self.container = get_container()\n  File \"/home/jclee/app/blacklist/tests/integration/../../src/core/containers/utils.py\", line 25, in get_container\n    _container = BlacklistContainer()\n  File \"/home/jclee/app/blacklist/tests/integration/../../src/core/containers/blacklist_container.py\", line 24, in __init__\n    self._configure_core_services()\n  File \"/home/jclee/app/blacklist/tests/integration/../../src/core/containers/blacklist_container.py\", line 34, in _configure_core_services\n    from ..blacklist_unified import UnifiedBlacklistManager\n  File \"/home/jclee/app/blacklist/tests/integration/../../src/core/blacklist_unified/__init__.py\", line 3, in <module>\n    from .manager import UnifiedBlacklistManager\n  File \"/home/jclee/app/blacklist/tests/integration/../../src/core/blacklist_unified/manager.py\", line 17, in <module>\n    from .statistics_service import StatisticsService\nModuleNotFoundError: No module named 'src.core.blacklist_unified.statistics_service'\n"
    }
  ]
}