{"created": 1754794824.7324183, "duration": 2.63320255279541, "exitcode": 1, "root": "/home/jclee/app/blacklist/tests", "environment": {}, "summary": {"failed": 1, "total": 1, "collected": 1}, "collectors": [{"nodeid": "", "outcome": "passed", "result": [{"nodeid": "integration/test_cicd_pipeline.py::TestDeploymentStage::test_argocd_application_sync", "type": "Function", "lineno": 225}]}], "tests": [{"nodeid": "integration/test_cicd_pipeline.py::TestDeploymentStage::test_argocd_application_sync", "lineno": 225, "outcome": "failed", "keywords": ["test_argocd_application_sync", "TestDeploymentStage", "test_cicd_pipeline.py", "integration", "tests", ""], "setup": {"duration": 0.3754742730525322, "outcome": "passed", "log": [{"name": "src.core.collection_manager.protection_service", "msg": "Error counting recent auth failures: no such table: auth_attempts", "args": null, "levelname": "ERROR", "levelno": 40, "pathname": "/home/jclee/app/blacklist/src/core/collection_manager/protection_service.py", "filename": "protection_service.py", "module": "protection_service", "exc_info": null, "exc_text": null, "stack_info": null, "lineno": 185, "funcName": "_count_recent_auth_failures", "created": 1754794822.4722962, "msecs": 472.0, "relativeCreated": 572.0181465148926, "thread": 131398304804864, "threadName": "MainThread", "processName": "MainProcess", "process": 3400783}, {"name": "src.core.collection_manager.protection_service", "msg": "Error counting recent auth failures: no such table: auth_attempts", "args": null, "levelname": "ERROR", "levelno": 40, "pathname": "/home/jclee/app/blacklist/src/core/collection_manager/protection_service.py", "filename": "protection_service.py", "module": "protection_service", "exc_info": null, "exc_text": null, "stack_info": null, "lineno": 185, "funcName": "_count_recent_auth_failures", "created": 1754794822.4729128, "msecs": 472.0, "relativeCreated": 572.6346969604492, "thread": 131398304804864, "threadName": "MainThread", "processName": "MainProcess", "process": 3400783}, {"name": "src.core.collection_manager.protection_service", "msg": "Error counting recent auth failures: no such table: auth_attempts", "args": null, "levelname": "ERROR", "levelno": 40, "pathname": "/home/jclee/app/blacklist/src/core/collection_manager/protection_service.py", "filename": "protection_service.py", "module": "protection_service", "exc_info": null, "exc_text": null, "stack_info": null, "lineno": 185, "funcName": "_count_recent_auth_failures", "created": 1754794822.473123, "msecs": 473.0, "relativeCreated": 572.8449821472168, "thread": 131398304804864, "threadName": "MainThread", "processName": "MainProcess", "process": 3400783}, {"name": "src.core.collection_manager.auth_service", "msg": "Error getting auth statistics: no such table: auth_attempts", "args": null, "levelname": "ERROR", "levelno": 40, "pathname": "/home/jclee/app/blacklist/src/core/collection_manager/auth_service.py", "filename": "auth_service.py", "module": "auth_service", "exc_info": null, "exc_text": null, "stack_info": null, "lineno": 172, "funcName": "get_auth_statistics", "created": 1754794822.4733303, "msecs": 473.0, "relativeCreated": 573.052167892456, "thread": 131398304804864, "threadName": "MainThread", "processName": "MainProcess", "process": 3400783}, {"name": "src.core.collection_manager.auth_service", "msg": "Database error checking auth limits: no such table: auth_attempts", "args": null, "levelname": "ERROR", "levelno": 40, "pathname": "/home/jclee/app/blacklist/src/core/collection_manager/auth_service.py", "filename": "auth_service.py", "module": "auth_service", "exc_info": null, "exc_text": null, "stack_info": null, "lineno": 52, "funcName": "check_auth_attempt_limit", "created": 1754794822.4736328, "msecs": 473.0, "relativeCreated": 573.3547210693359, "thread": 131398304804864, "threadName": "MainThread", "processName": "MainProcess", "process": 3400783}, {"name": "src.core.collection_manager.auth_service", "msg": "Error getting auth statistics: no such table: auth_attempts", "args": null, "levelname": "ERROR", "levelno": 40, "pathname": "/home/jclee/app/blacklist/src/core/collection_manager/auth_service.py", "filename": "auth_service.py", "module": "auth_service", "exc_info": null, "exc_text": null, "stack_info": null, "lineno": 172, "funcName": "get_auth_statistics", "created": 1754794822.4738503, "msecs": 473.0, "relativeCreated": 573.5721588134766, "thread": 131398304804864, "threadName": "MainThread", "processName": "MainProcess", "process": 3400783}, {"name": "src.core.collection_manager.auth_service", "msg": "Database error checking auth limits: no such table: auth_attempts", "args": null, "levelname": "ERROR", "levelno": 40, "pathname": "/home/jclee/app/blacklist/src/core/collection_manager/auth_service.py", "filename": "auth_service.py", "module": "auth_service", "exc_info": null, "exc_text": null, "stack_info": null, "lineno": 52, "funcName": "check_auth_attempt_limit", "created": 1754794822.4741805, "msecs": 474.0, "relativeCreated": 573.9023685455322, "thread": 131398304804864, "threadName": "MainThread", "processName": "MainProcess", "process": 3400783}, {"name": "src.core.collection_manager.auth_service", "msg": "Error getting auth statistics: no such table: auth_attempts", "args": null, "levelname": "ERROR", "levelno": 40, "pathname": "/home/jclee/app/blacklist/src/core/collection_manager/auth_service.py", "filename": "auth_service.py", "module": "auth_service", "exc_info": null, "exc_text": null, "stack_info": null, "lineno": 172, "funcName": "get_auth_statistics", "created": 1754794822.474557, "msecs": 474.0, "relativeCreated": 574.2788314819336, "thread": 131398304804864, "threadName": "MainThread", "processName": "MainProcess", "process": 3400783}]}, "call": {"duration": 0.000371559988707304, "outcome": "failed", "crash": {"path": "/home/jclee/app/blacklist/tests/integration/test_cicd_pipeline.py", "lineno": 229, "message": "AssertionError: assert False\n +  where False = exists()\n +    where exists = PosixPath('k8s/argocd-app-clean.yaml').exists"}, "traceback": [{"path": "tests/integration/test_cicd_pipeline.py", "lineno": 229, "message": "in test_argocd_application_sync"}], "longrepr": "tests/integration/test_cicd_pipeline.py:229: in test_argocd_application_sync\n    assert argocd_app_path.exists()\nE   AssertionError: assert False\nE    +  where False = exists()\nE    +    where exists = PosixPath('k8s/argocd-app-clean.yaml').exists"}, "teardown": {"duration": 0.0003959860187023878, "outcome": "passed"}}]}