{"created": 1754707012.3911567, "duration": 2.203509569168091, "exitcode": 1, "root": "/home/jclee/app/blacklist/tests", "environment": {}, "summary": {"passed": 4, "total": 4, "collected": 4}, "collectors": [{"nodeid": "", "outcome": "passed", "result": [{"nodeid": "test_cicd_modules.py", "type": "Module"}, {"nodeid": "test_collection_mocks.py", "type": "Module"}]}, {"nodeid": "test_cicd_modules.py", "outcome": "passed", "result": [{"nodeid": "test_cicd_modules.py::test_imports", "type": "Function", "lineno": 7}, {"nodeid": "test_cicd_modules.py::test_functionality", "type": "Function", "lineno": 21}, {"nodeid": "test_cicd_modules.py::test_integration", "type": "Function", "lineno": 54}, {"nodeid": "test_cicd_modules.py::test_line_count_compliance", "type": "Function", "lineno": 85}]}, {"nodeid": "test_collection_mocks.py", "outcome": "passed", "result": []}], "tests": [{"nodeid": "test_cicd_modules.py::test_imports", "lineno": 7, "outcome": "passed", "keywords": ["test_imports", "test_cicd_modules.py", "__init__.py", "tests"], "setup": {"duration": 0.4464048750232905, "outcome": "passed", "log": [{"name": "src.core.collection_manager.protection_service", "msg": "Error counting recent auth failures: no such table: auth_attempts", "args": null, "levelname": "ERROR", "levelno": 40, "pathname": "/home/jclee/app/blacklist/src/core/collection_manager/protection_service.py", "filename": "protection_service.py", "module": "protection_service", "exc_info": null, "exc_text": null, "stack_info": null, "lineno": 185, "funcName": "_count_recent_auth_failures", "created": 1754707010.6318226, "msecs": 631.0, "relativeCreated": 665.3823852539062, "thread": 136404338487296, "threadName": "MainThread", "processName": "MainProcess", "process": 2808667}, {"name": "src.core.collection_manager.protection_service", "msg": "Error counting recent auth failures: no such table: auth_attempts", "args": null, "levelname": "ERROR", "levelno": 40, "pathname": "/home/jclee/app/blacklist/src/core/collection_manager/protection_service.py", "filename": "protection_service.py", "module": "protection_service", "exc_info": null, "exc_text": null, "stack_info": null, "lineno": 185, "funcName": "_count_recent_auth_failures", "created": 1754707010.6323812, "msecs": 632.0, "relativeCreated": 665.9409999847412, "thread": 136404338487296, "threadName": "MainThread", "processName": "MainProcess", "process": 2808667}, {"name": "src.core.collection_manager.protection_service", "msg": "Error counting recent auth failures: no such table: auth_attempts", "args": null, "levelname": "ERROR", "levelno": 40, "pathname": "/home/jclee/app/blacklist/src/core/collection_manager/protection_service.py", "filename": "protection_service.py", "module": "protection_service", "exc_info": null, "exc_text": null, "stack_info": null, "lineno": 185, "funcName": "_count_recent_auth_failures", "created": 1754707010.6326091, "msecs": 632.0, "relativeCreated": 666.1689281463623, "thread": 136404338487296, "threadName": "MainThread", "processName": "MainProcess", "process": 2808667}, {"name": "src.core.collection_manager.auth_service", "msg": "Error getting auth statistics: no such table: auth_attempts", "args": null, "levelname": "ERROR", "levelno": 40, "pathname": "/home/jclee/app/blacklist/src/core/collection_manager/auth_service.py", "filename": "auth_service.py", "module": "auth_service", "exc_info": null, "exc_text": null, "stack_info": null, "lineno": 172, "funcName": "get_auth_statistics", "created": 1754707010.6328204, "msecs": 632.0, "relativeCreated": 666.3801670074463, "thread": 136404338487296, "threadName": "MainThread", "processName": "MainProcess", "process": 2808667}, {"name": "src.core.collection_manager.auth_service", "msg": "Database error checking auth limits: no such table: auth_attempts", "args": null, "levelname": "ERROR", "levelno": 40, "pathname": "/home/jclee/app/blacklist/src/core/collection_manager/auth_service.py", "filename": "auth_service.py", "module": "auth_service", "exc_info": null, "exc_text": null, "stack_info": null, "lineno": 52, "funcName": "check_auth_attempt_limit", "created": 1754707010.6331244, "msecs": 633.0, "relativeCreated": 666.6841506958008, "thread": 136404338487296, "threadName": "MainThread", "processName": "MainProcess", "process": 2808667}, {"name": "src.core.collection_manager.auth_service", "msg": "Error getting auth statistics: no such table: auth_attempts", "args": null, "levelname": "ERROR", "levelno": 40, "pathname": "/home/jclee/app/blacklist/src/core/collection_manager/auth_service.py", "filename": "auth_service.py", "module": "auth_service", "exc_info": null, "exc_text": null, "stack_info": null, "lineno": 172, "funcName": "get_auth_statistics", "created": 1754707010.6333494, "msecs": 633.0, "relativeCreated": 666.9092178344727, "thread": 136404338487296, "threadName": "MainThread", "processName": "MainProcess", "process": 2808667}, {"name": "src.core.collection_manager.auth_service", "msg": "Database error checking auth limits: no such table: auth_attempts", "args": null, "levelname": "ERROR", "levelno": 40, "pathname": "/home/jclee/app/blacklist/src/core/collection_manager/auth_service.py", "filename": "auth_service.py", "module": "auth_service", "exc_info": null, "exc_text": null, "stack_info": null, "lineno": 52, "funcName": "check_auth_attempt_limit", "created": 1754707010.63365, "msecs": 633.0, "relativeCreated": 667.2098636627197, "thread": 136404338487296, "threadName": "MainThread", "processName": "MainProcess", "process": 2808667}, {"name": "src.core.collection_manager.auth_service", "msg": "Error getting auth statistics: no such table: auth_attempts", "args": null, "levelname": "ERROR", "levelno": 40, "pathname": "/home/jclee/app/blacklist/src/core/collection_manager/auth_service.py", "filename": "auth_service.py", "module": "auth_service", "exc_info": null, "exc_text": null, "stack_info": null, "lineno": 172, "funcName": "get_auth_statistics", "created": 1754707010.6338613, "msecs": 633.0, "relativeCreated": 667.4211025238037, "thread": 136404338487296, "threadName": "MainThread", "processName": "MainProcess", "process": 2808667}]}, "call": {"duration": 0.0002424769918434322, "outcome": "passed", "stdout": "\ud83d\udce6 Testing module imports...\n\u2705 All imports successful\n"}, "teardown": {"duration": 0.0004753560060635209, "outcome": "passed"}}, {"nodeid": "test_cicd_modules.py::test_functionality", "lineno": 21, "outcome": "passed", "keywords": ["test_functionality", "test_cicd_modules.py", "__init__.py", "tests"], "setup": {"duration": 0.0017390790162608027, "outcome": "passed"}, "call": {"duration": 0.0003173489822074771, "outcome": "passed", "stdout": "\ud83d\udd27 Testing basic functionality...\n\u274c Functionality test failed: No module named 'tests.cicd_error_patterns'\n"}, "teardown": {"duration": 0.0002845670096576214, "outcome": "passed"}}, {"nodeid": "test_cicd_modules.py::test_integration", "lineno": 54, "outcome": "passed", "keywords": ["test_integration", "test_cicd_modules.py", "__init__.py", "tests"], "setup": {"duration": 0.0015380600234493613, "outcome": "passed"}, "call": {"duration": 0.0003209359711036086, "outcome": "passed", "stdout": "\ud83d\udd0d Testing module integration...\n\u274c Integration test failed: No module named 'tests.cicd_troubleshooter'\n"}, "teardown": {"duration": 0.0003559109754860401, "outcome": "passed"}}, {"nodeid": "test_cicd_modules.py::test_line_count_compliance", "lineno": 85, "outcome": "passed", "keywords": ["test_line_count_compliance", "test_cicd_modules.py", "__init__.py", "tests"], "setup": {"duration": 0.0016002180054783821, "outcome": "passed"}, "call": {"duration": 0.000510864017996937, "outcome": "passed", "stdout": "\ud83d\udcca Testing 500-line compliance...\n"}, "teardown": {"duration": 0.00040335103403776884, "outcome": "passed"}}]}